Traceback (most recent call last):
  File "/opt/hostedtoolcache/Python/3.10.18/x64/lib/python3.10/site-packages/jupyter_core/utils/__init__.py", line 154, in wrapped
    asyncio.get_running_loop()
RuntimeError: no running event loop

During handling of the above exception, another exception occurred:

Traceback (most recent call last):
  File "/opt/hostedtoolcache/Python/3.10.18/x64/lib/python3.10/site-packages/jupyter_cache/executors/utils.py", line 58, in single_nb_execution
    executenb(
  File "/opt/hostedtoolcache/Python/3.10.18/x64/lib/python3.10/site-packages/nbclient/client.py", line 1319, in execute
    return NotebookClient(nb=nb, resources=resources, km=km, **kwargs).execute()
  File "/opt/hostedtoolcache/Python/3.10.18/x64/lib/python3.10/site-packages/jupyter_core/utils/__init__.py", line 158, in wrapped
    return loop.run_until_complete(inner)
  File "/opt/hostedtoolcache/Python/3.10.18/x64/lib/python3.10/asyncio/base_events.py", line 649, in run_until_complete
    return future.result()
  File "/opt/hostedtoolcache/Python/3.10.18/x64/lib/python3.10/site-packages/nbclient/client.py", line 709, in async_execute
    await self.async_execute_cell(
  File "/opt/hostedtoolcache/Python/3.10.18/x64/lib/python3.10/site-packages/nbclient/client.py", line 1062, in async_execute_cell
    await self._check_raise_for_error(cell, cell_index, exec_reply)
  File "/opt/hostedtoolcache/Python/3.10.18/x64/lib/python3.10/site-packages/nbclient/client.py", line 918, in _check_raise_for_error
    raise CellExecutionError.from_cell_and_msg(cell, exec_reply_content)
nbclient.exceptions.CellExecutionError: An error occurred while executing the following cell:
------------------
# Ganti dengan kredensial database PostgreSQL Anda
db_user = 'avnadmin'
db_password = 'AVNS_9tlb724wsVZP8tiktZC'
db_host = 'zulfri-psd-data-science-zulfri.f.aivencloud.com'
db_port = '18222'
db_name = 'defaultdb'

# Membuat connection string
conn_string = f'postgresql://{db_user}:{db_password}@{db_host}:{db_port}/{db_name}'

# Membuat engine koneksi ke database
try:
    engine = create_engine(conn_string)
    print("Koneksi ke database PostgreSQL berhasil!")
except Exception as e:
    print(f"Terjadi kesalahan saat koneksi: {e}")

# --- PENGAMBILAN DATA ---
# Tulis query SQL untuk mengambil data yang Anda butuhkan
sql_query = "SELECT * FROM data_penjualan;"

# Mengambil data menggunakan pandas dan koneksi engine
try:
    df = pd.read_sql(sql_query, engine)
    print("Data berhasil diambil dari tabel.")
except Exception as e:
    print(f"Terjadi kesalahan saat mengambil data: {e}")

# Menampilkan 5 baris pertama dari data untuk memastikan data berhasil dimuat
df.head()
------------------

----- stdout -----
Koneksi ke database PostgreSQL berhasil!
Terjadi kesalahan saat mengambil data: (psycopg2.OperationalError) could not translate host name "zulfri-psd-data-science-zulfri.f.aivencloud.com" to address: Name or service not known

(Background on this error at: https://sqlalche.me/e/20/e3q8)
------------------

[0;31m---------------------------------------------------------------------------[0m
[0;31mNameError[0m                                 Traceback (most recent call last)
Cell [0;32mIn[2], line 30[0m
[1;32m     27[0m     [38;5;28mprint[39m([38;5;124mf[39m[38;5;124m"[39m[38;5;124mTerjadi kesalahan saat mengambil data: [39m[38;5;132;01m{[39;00me[38;5;132;01m}[39;00m[38;5;124m"[39m)
[1;32m     29[0m [38;5;66;03m# Menampilkan 5 baris pertama dari data untuk memastikan data berhasil dimuat[39;00m
[0;32m---> 30[0m [43mdf[49m[38;5;241m.[39mhead()

[0;31mNameError[0m: name 'df' is not defined

